Workbook

Sheet Raw_Data
A1: Bank | B1: Year | C1: Net_Profit | D1: Total_Assets_Current | E1: Total_Assets_Prior | F1: Total_Equity_Current | G1: Total_Equity_Prior | H1: Net_Interest_Income | I1: Operating_Expenses | J1: Operating_Income | K1: NPLs | L1: Gross_Loans | M1: Source | N1: Thousands of Georgian Lari
A2: BoG | B2: 2018 | C2: 343528 | D2: 14523587 | E2: 12620716 | F2: 1731028 | G2: 1481919 | H2: 731544 | I2: 356541 | J2: 991714 | K2: =187641+39045+82223+26694+369 -> 335972 | L2: 9431145 | M2: pp: 1,2,37,70
A3: BoG | B3: 2019 | C3: 512887 | D3: 18323223 | E3: 14523587 | F3: 2077397 | G3: 1731028 | H3: 783573 | I3: 398575 | J3: 1072173 | K3: =134963+26072+73861+24404+101 -> 259401 | L3: 11826994 | M3: pp: 1,2,51,78
A4: BoG | B4: 2020 | C4: 306498 | D4: 21768306 | E4: 18323223 | F4: 2488300 | G4: 2077397 | H4: 764996 | I4: 391987 | J4: 1043379 | K4: =237966+116434+145029+68384+406 -> 568219 | L4: 14306433 | M4: pp:11,12,45,90
A5: BoG | B5: 2021 | C5: 743811 | D5: 23161212 | E5: 21768306 | F5: 3051223 | G5: 2488300 | H5: 940883 | I5: 461215 | J5: 1304531 | K5: =223017+34907+117919+42898+1003 -> 419744 | L5: 16280932 | M5: pp: 9,10,88
A6: BoG | B6: 2022 | C6: 992004 | D6: 28367058 | E6: 23161212 | F6: 3787368 | G6: 2051223 | H6: 1174611 | I6: 581668 | J6: 1931327 | K6: =184114+66723+137623+82164+1318 -> 471942 | L6: 17079086 | M6: pp:10,11,44,79,89
A7: BoG | B7: 2023 | C7: 1333719 | D7: 31394110 | E7: 28367058 | F7: 4452050 | G7: 3787368 | H7: 1586000 | I7: 678955 | J7: 2412629 | K7: =120202+53985+169870+107674+2566 -> 454297 | L7: 20511705 | M7: pp:9,11,44,79,89,90
A8: BoG | B8: 2024 | C8: 1837899 | D8: 39273163 | E8: 31394110 | F8: 5630498 | G8: 4452050 | H8: 1842747 | I8: 790163 | J8: 2726729 | K8: =185664+66963+184979+117124+2727 -> 557457 | L8: 24220743 | M8: pp:8,10,42,81,92
A9: TBC | B9: 2018 | C9: 433300 | D9: 15452888 | E9: 12937198 | F9: 2111757 | G9: 1848362 | H9: 770558 | I9: 395932 | J9: 1066089 | K9: 321550 | L9: 10372582 | M9: pp:86,102,104
A10: TBC | B10: 2019 | C10: 545685 | D10: 18306618 | E10: 15452888 | F10: 2531710 | G10: 2111757 | H10: 793240 | I10: 412359 | J10: 1093178 | K10: 341873 | L10: 12661955 | M10: pp:92,113,115
A11: TBC | B11: 2020 | C11: 337260 | D11: 22398962 | E11: 18306618 | F11: 2830180 | G11: 2531710 | H11: 827699 | I11: 391299 | J11: 1115063 | K11: 714424 | L11: 15200515 | M11: pp:113,120,121,122
A12: TBC | B12: 2021 | C12: 842945 | D12: 24039512 | E12: 22398962 | F12: 3590055 | G12: 2830180 | H12: 995792 | I12: 454993 | J12: 1397908 | K12: 406909 | L12: 16954553 | M12: pp:74,125,126
A13: TBC | B13: 2022 | C13: 1023075 | D13: 28329010 | E13: 24039512 | F13: 4265802 | G13: 3590055 | H13: 1243095 | I13: 560982 | J13: 1946389 | K13: 392860 | L13: 17857276 | M13: pp:34,71
A14: TBC | B14: 2023 | C14: 1119058 | D14: 31771136 | E14: 28329010 | F14: 4747709 | G14: 4265802 | H14: 1495596 | I14: 681762 | J14: 2132112 | K14: 425535 | L14: 21276749 | M14: pp:44,81,86
A15: TBC | B15: 2024 | C15: 1244716 | D15: 37655290 | E15: 31771136 | F15: 5454829 | G15: 4747709 | H15: 1590992 | I15: 779484 | J15: 2373954 | K15: 539431 | L15: 24519589 | M15: pp:34,35,92
A16: Basis | B16: 2018 | C16: 37292 | D16: 1435790 | E16: 1231599 | F16: 249534 | G16: 213491 | H16: 55718 | I16: 25858 | J16: 69383 | K16: 40666 | L16: 916451 | M16: pp:6,7,43,48,49
A17: Basis | B17: 2019 | C17: 37327 | D17: 1700912 | E17: 1435790 | F17: 283638 | G17: 249534 | H17: 59437 | I17: 32442 | J17: 74000 | K17: 53568 | L17: 1000429 | M17: pp: 7, 30, 56, 57, 47
A18: Basis | B18: 2020 | C18: 24221 | D18: 2068738 | E18: 1700912 | F18: 308890 | G18: 283638 | H18: 54394 | I18: 31197 | J18: 66503 | K18: 82955 | L18: 1101318 | M18: pp: 7,34,48,61,64
A19: Basis | B19: 2021 | C19: 38581 | D19: 1929664 | E19: 2068738 | F19: 351405 | G19: 308890 | H19: 67918 | I19: 41160 | J19: 82461 | K19: 59916 | L19: 1263319 | M19: pp: 7,46,49,56,57
A20: Basis | B20: 2022 | C20: 74054 | D20: 3190361 | E20: 1929664 | F20: 454474 | G20: 351405 | H20: 125841 | I20: 72110 | J20: 151286 | K20: 82976 | L20: 2121190 | M20: pp: 8,10,43,52,55,62
... A36: VTB | B36: 2024 | C36: 8410 | D36: 450554 | E36: 452928 | F36: 330580 | G36: 321343 | H36: 7549 | I36: 14421 | J36: 30911 | K36: 114156 | L36: 194982 | M36: pp:5,6,26,30

Sheet Net Profit Growth
A1: Bank | B1: Year | C1: Net_Profit
A2: BoG | B2: 2018 | C2: 343528
A3: BoG | B3: 2019 | C3: 512887
A4: BoG | B4: 2020 | C4: 306498
A5: BoG | B5: 2021 | C5: 743811
A6: BoG | B6: 2022 | C6: 992004
A7: BoG | B7: 2023 | C7: 1333719
A8: BoG | B8: 2024 | C8: 1837899
A9: TBC | B9: 2018 | C9: 433300
A10: TBC | B10: 2019 | C10: 545685
A11: TBC | B11: 2020 | C11: 337260
A12: TBC | B12: 2021 | C12: 842945
A13: TBC | B13: 2022 | C13: 1023075
... A16: Basis | B16: 2018 | C16: 37292
A17: Basis | B17: 2019 | C17: 37327 | F17: Sum of Net_Profit | G17: Column Labels
A18: Basis | B18: 2020 | C18: 24221 | F18: Row Labels | G18: VTB | H18: Credo | I18: Basis | J18: TBC | K18: BoG | L18: Grand Total
A19: Basis | B19: 2021 | C19: 38581 | F19: 2018 | G19: 26949 | H19: 20191 | I19: 37292 | J19: 433300 | K19: 343528 | L19: 861260
A20: Basis | B20: 2022 | C20: 74054 | F20: 2019 | G20: 29755 | H20: 29539 | I20: 37327 | J20: 545685 | K20: 512887 | L20: 1155193
A21: Basis | B21: 2023 | C21: 76885 | F21: 2020 | G21: 26714 | H21: 10858 | I21: 24221 | J21: 337260 | K21: 306498 | L21: 705551
A22: Basis | B22: 2024 | C22: 87423 | F22: 2021 | G22: 33995 | H22: 36710 | I22: 38581 | J22: 842945 | K22: 743811 | L22: 1696042
A23: Credo | B23: 2018 | C23: 20191 | F23: 2022 | G23: -83562 | H23: 45211 | I23: 74054 | J23: 1023075 | K23: 992004 | L23: 2050782
A24: Credo | B24: 2019 | C24: 29539 | F24: 2023 | G24: 400 | H24: 41073 | I24: 76885 | J24: 1119058 | K24: 1333719 | L24: 2571135
A25: Credo | B25: 2020 | C25: 10858 | F25: 2024 | G25: 8410 | H25: 68605 | I25: 87423 | J25: 1244716 | K25: 1837899 | L25: 3247053
A26: Credo | B26: 2021 | C26: 36710 | F26: Grand Total | G26: 42661 | H26: 252187 | I26: 375783 | J26: 5546039 | K26: 6070346 | L26: 12287016
A27: Credo | B27: 2022 | C27: 45211
A28: Credo | B28: 2023 | C28: 41073
A29: Credo | B29: 2024 | C29: 68605
A30: VTB | B30: 2018 | C30: 26949
A31: VTB | B31: 2019 | C31: 29755
A32: VTB | B32: 2020 | C32: 26714
A33: VTB | B33: 2021 | C33: 33995
A34: VTB | B34: 2022 | C34: -83562
A35: VTB | B35: 2023 | C35: 400
A36: VTB | B36: 2024 | C36: 8410

Sheet Calculated_Ratios
A1: Bank | B1: Year | C1: ROA | D1: ROE | E1: NIM_approx | F1: CIR | G1: NPL_Ratio | H1: Loan-to-Asset Ratio | I1: Equity Multiplier
A2: BoG | B2: 2018 | C2: =(Raw_Data!C2)/((Raw_Data!D2+Raw_Data!E2)/2) -> 0.025311241 | D2: =(Raw_Data!C2)/((Raw_Data!F2+Raw_Data!G2)/2) -> 0.21383982 | E2: =(Raw_Data!H2)/((Raw_Data!D2+Raw_Data!E2)/2) -> 0.053900371 | F2: =Raw_Data!I2/Raw_Data!J2 -> 0.35951998 | G2: =Raw_Data!K2/Raw_Data!L2 -> 0.03562367 | H2: =Raw_Data!L2/(Raw_Data!E2+Raw_Data!D2) -> 0.34744473 | I2: =(Raw_Data!D2+Raw_Data!E2)/(Raw_Data!F2+Raw_Data!G2) -> 8.4484129
A3: BoG | B3: 2019 | C3: =(Raw_Data!C3)/((Raw_Data!D3+Raw_Data!E3)/2) -> 0.03122903 | D3: =(Raw_Data!C3)/((Raw_Data!F3+Raw_Data!G3)/2) -> 0.26934336 | E3: =(Raw_Data!H3)/((Raw_Data!D3+Raw_Data!E3)/2) -> 0.047710752 | F3: =Raw_Data!I3/Raw_Data!J3 -> 0.37174504 | G3: =Raw_Data!K3/Raw_Data!L3 -> 0.021932961 | H3: =Raw_Data!L3/(Raw_Data!E3+Raw_Data!D3) -> 0.36006522 | I3: =(Raw_Data!D3+Raw_Data!E3)/(Raw_Data!F3+Raw_Data!G3) -> 8.6247753
A4: BoG | B4: 2020 | C4: =(Raw_Data!C4)/((Raw_Data!D4+Raw_Data!E4)/2) -> 0.015289913 | D4: =(Raw_Data!C4)/((Raw_Data!F4+Raw_Data!G4)/2) -> 0.13426121 | E4: =(Raw_Data!H4)/((Raw_Data!D4+Raw_Data!E4)/2) -> 0.038162476 | F4: =Raw_Data!I4/Raw_Data!J4 -> 0.37568995 | G4: =Raw_Data!K4/Raw_Data!L4 -> 0.039717727 | H4: =Raw_Data!L4/(Raw_Data!E4+Raw_Data!D4) -> 0.35684428 | I4: =(Raw_Data!D4+Raw_Data!E4)/(Raw_Data!F4+Raw_Data!G4) -> 8.7810315
A5: BoG | B5: 2021 | C5: =(Raw_Data!C5)/((Raw_Data!D5+Raw_Data!E5)/2) -> 0.033110126 | D5: =(Raw_Data!C5)/((Raw_Data!F5+Raw_Data!G5)/2) -> 0.26854695 | E5: =(Raw_Data!H5)/((Raw_Data!D5+Raw_Data!E5)/2) -> 0.041882622 | F5: =Raw_Data!I5/Raw_Data!J5 -> 0.35354852 | G5: =Raw_Data!K5/Raw_Data!L5 -> 0.025781325 | H5: =Raw_Data!L5/(Raw_Data!E5+Raw_Data!D5) -> 0.36236605 | I5: =(Raw_Data!D5+Raw_Data!E5)/(Raw_Data!F5+Raw_Data!G5) -> 8.1107196
A6: BoG | B6: 2022 | C6: =(Raw_Data!C6)/((Raw_Data!D6+Raw_Data!E6)/2) -> 0.038503291 | D6: =(Raw_Data!C6)/((Raw_Data!F6+Raw_Data!G6)/2) -> 0.33980938 | E6: =(Raw_Data!H6)/((Raw_Data!D6+Raw_Data!E6)/2) -> 0.045590935 | F6: =Raw_Data!I6/Raw_Data!J6 -> 0.30117531 | G6: =Raw_Data!K6/Raw_Data!L6 -> 0.027632743 | H6: =Raw_Data!L6/(Raw_Data!E6+Raw_Data!D6) -> 0.33145079 | I6: =(Raw_Data!D6+Raw_Data!E6)/(Raw_Data!F6+Raw_Data!G6) -> 8.8254632
A7: BoG | B7: 2023 | C7: =(Raw_Data!C7)/((Raw_Data!D7+Raw_Data!E7)/2) -> 0.044634971 | D7: =(Raw_Data!C7)/((Raw_Data!F7+Raw_Data!G7)/2) -> 0.32374107 | E7: =(Raw_Data!H7)/((Raw_Data!D7+Raw_Data!E7)/2) -> 0.053077945 | F7: =Raw_Data!I7/Raw_Data!J7 -> 0.28141708 | G7: =Raw_Data!K7/Raw_Data!L7 -> 0.022148183 | H7: =Raw_Data!L7/(Raw_Data!E7+Raw_Data!D7) -> 0.34322798 | I7: =(Raw_Data!D7+Raw_Data!E7)/(Raw_Data!F7+Raw_Data!G7) -> 7.2530812
A8: BoG | B8: 2024 | C8: =(Raw_Data!C8)/((Raw_Data!D8+Raw_Data!E8)/2) -> 0.052015563 | D8: =(Raw_Data!C8)/((Raw_Data!F8+Raw_Data!G8)/2) -> 0.36457034 | E8: =(Raw_Data!H8)/((Raw_Data!D8+Raw_Data!E8)/2) -> 0.05215277 | F8: =Raw_Data!I8/Raw_Data!J8 -> 0.28978421 | G8: =Raw_Data!K8/Raw_Data!L8 -> 0.023015685 | H8: =Raw_Data!L8/(Raw_Data!E8+Raw_Data!D8) -> 0.34274342 | I8: =(Raw_Data!D8+Raw_Data!E8)/(Raw_Data!F8+Raw_Data!G8) -> 7.0088705
A9: TBC | B9: 2018 | C9: =(Raw_Data!C9)/((Raw_Data!D9+Raw_Data!E9)/2) -> 0.03052474 | D9: =(Raw_Data!C9)/((Raw_Data!F9+Raw_Data!G9)/2) -> 0.21883181 | E9: =(Raw_Data!H9)/((Raw_Data!D9+Raw_Data!E9)/2) -> 0.054283597 | F9: =Raw_Data!I9/Raw_Data!J9 -> 0.37138738 | G9: =Raw_Data!K9/Raw_Data!L9 -> 0.030999996 | H9: =Raw_Data!L9/(Raw_Data!E9+Raw_Data!D9) -> 0.3653593 | I9: =(Raw_Data!D9+Raw_Data!E9)/(Raw_Data!F9+Raw_Data!G9) -> 7.1689982
A10: TBC | B10: 2019 | C10: =(Raw_Data!C10)/((Raw_Data!D10+Raw_Data!E10)/2) -> 0.032327783 | D10: =(Raw_Data!C10)/((Raw_Data!F10+Raw_Data!G10)/2) -> 0.23503344 | E10: =(Raw_Data!H10)/((Raw_Data!D10+Raw_Data!E10)/2) -> 0.046993579 | F10: =Raw_Data!I10/Raw_Data!J10 -> 0.37721121 | G10: =Raw_Data!K10/Raw_Data!L10 -> 0.027000017 | H10: =Raw_Data!L10/(Raw_Data!E10+Raw_Data!D10) -> 0.3750634 | I10: =(Raw_Data!D10+Raw_Data!E10)/(Raw_Data!F10+Raw_Data!G10) -> 7.2703232
A11: TBC | B11: 2020 | C11: =(Raw_Data!C11)/((Raw_Data!D11+Raw_Data!E11)/2) -> 0.016570701 | D11: =(Raw_Data!C11)/((Raw_Data!F11+Raw_Data!G11)/2) -> 0.12579893 | E11: =(Raw_Data!H11)/((Raw_Data!D11+Raw_Data!E11)/2) -> 0.040667594 | F11: =Raw_Data!I11/Raw_Data!J11 -> 0.35092098 | G11: =Raw_Data!K11/Raw_Data!L11 -> 0.046999987 | H11: =Raw_Data!L11/(Raw_Data!E11+Raw_Data!D11) -> 0.37342583 | I11: =(Raw_Data!D11+Raw_Data!E11)/(Raw_Data!F11+Raw_Data!G11) -> 7.5916477
A12: TBC | B12: 2021 | C12: =(Raw_Data!C12)/((Raw_Data!D12+Raw_Data!E12)/2) -> 0.036303734 | D12: =(Raw_Data!C12)/((Raw_Data!F12+Raw_Data!G12)/2) -> 0.26259008 | E12: =(Raw_Data!H12)/((Raw_Data!D12+Raw_Data!E12)/2) -> 0.042886508 | F12: =Raw_Data!I12/Raw_Data!J12 -> 0.32548136 | G12: =Raw_Data!K12/Raw_Data!L12 -> 0.023999984 | H12: =Raw_Data!L12/(Raw_Data!E12+Raw_Data!D12) -> 0.36509712 | I12: =(Raw_Data!D12+Raw_Data!E12)/(Raw_Data!F12+Raw_Data!G12) -> 7.2331424
A13: TBC | B13: 2022 | C13: =(Raw_Data!C13)/((Raw_Data!D13+Raw_Data!E13)/2) -> 0.039072136 | D13: =(Raw_Data!C13)/((Raw_Data!F13+Raw_Data!G13)/2) -> 0.26046172 | E13: =(Raw_Data!H13)/((Raw_Data!D13+Raw_Data!E13)/2) -> 0.047474893 | F13: =Raw_Data!I13/Raw_Data!J13 -> 0.2882168 | G13: =Raw_Data!K13/Raw_Data!L13 -> 0.021999996 | H13: =Raw_Data!L13/(Raw_Data!E13+Raw_Data!D13) -> 0.34099255 | I13: =(Raw_Data!D13+Raw_Data!E13)/(Raw_Data!F13+Raw_Data!G13) -> 6.6661756
... A36: VTB | B36: 2024 | C36: =(Raw_Data!C36)/((Raw_Data!D36+Raw_Data!E36)/2) -> 0.018616862 | D36: =(Raw_Data!C36)/((Raw_Data!F36+Raw_Data!G36)/2) -> 0.025800593 | E36: =(Raw_Data!H36)/((Raw_Data!D36+Raw_Data!E36)/2) -> 0.016710903 | F36: =Raw_Data!I36/Raw_Data!J36 -> 0.46653295 | G36: =Raw_Data!K36/Raw_Data!L36 -> 0.58546943 | H36: =Raw_Data!L36/(Raw_Data!E36+Raw_Data!D36) -> 0.21581172 | I36: =(Raw_Data!D36+Raw_Data!E36)/(Raw_Data!F36+Raw_Data!G36) -> 1.3858723
C38: Return on Assets | D38: Return on Equity | E38: Net Interest Margin | F38: Cost-to- Income Ratio | G38: NPL Ratio | H38: Loan-to-Asset Ratio | I38: Equity Multiplier
C40: =Net Profit / Average Total Assets | D40: =Net Profit / Average Total Equity | E40: =Net interest Income / Average Total Assets | F40: =Operating Expenses / Operating Income | G40: =NPLs / Gross Loans | H40: =Gross Loans / Average Total Assets | I40: =Average Total Assets / Average Total Equity

Sheet Industry Benchmark Analysis
A1: Year | B1: Avg_ROA | C1: Avg_ROE | D1: Avg_NIM | E1: Avg_CIR | F1: Avg_NPL | G1: Avg_Loan_to_Asset | H1: Average_Equity_Multiplier
A2: 2018 | B2: =AVERAGEIFS(Calculated_Ratios!C:C, Calculated_Ratios!B:B, A2) -> 0.025886061 | C2: =AVERAGEIFS(Calculated_Ratios!D:D, Calculated_Ratios!B:B, A2) -> 0.17338681 | D2: =AVERAGEIFS(Calculated_Ratios!E:E, Calculated_Ratios!B:B, A2) -> 0.067418097 | E2: =AVERAGEIFS(Calculated_Ratios!F:F, Calculated_Ratios!B:B, A2) -> 0.47914859 | F2: =AVERAGEIFS(Calculated_Ratios!G:G, Calculated_Ratios!B:B, A2) -> 0.029540774 | G2: =AVERAGEIFS(Calculated_Ratios!H:H, Calculated_Ratios!B:B, A2) -> 0.37976 | H2: =AVERAGEIFS(Calculated_Ratios!I:I, Calculated_Ratios!B:B, A2) -> 6.7330585
A3: 2019 | B3: =AVERAGEIFS(Calculated_Ratios!C:C, Calculated_Ratios!B:B, A3) -> 0.02764774 | C3: =AVERAGEIFS(Calculated_Ratios!D:D, Calculated_Ratios!B:B, A3) -> 0.19284874 | D3: =AVERAGEIFS(Calculated_Ratios!E:E, Calculated_Ratios!B:B, A3) -> 0.061215422 | E3: =AVERAGEIFS(Calculated_Ratios!F:F, Calculated_Ratios!B:B, A3) -> 0.49458332 | F3: =AVERAGEIFS(Calculated_Ratios!G:G, Calculated_Ratios!B:B, A3) -> 0.029268537 | G3: =AVERAGEIFS(Calculated_Ratios!H:H, Calculated_Ratios!B:B, A3) -> 0.37657148 | H3: =AVERAGEIFS(Calculated_Ratios!I:I, Calculated_Ratios!B:B, A3) -> 6.8621206
A4: 2020 | B4: =AVERAGEIFS(Calculated_Ratios!C:C, Calculated_Ratios!B:B, A4) -> 0.013577728 | C4: =AVERAGEIFS(Calculated_Ratios!D:D, Calculated_Ratios!B:B, A4) -> 0.10012467 | D4: =AVERAGEIFS(Calculated_Ratios!E:E, Calculated_Ratios!B:B, A4) -> 0.050159718 | E4: =AVERAGEIFS(Calculated_Ratios!F:F, Calculated_Ratios!B:B, A4) -> 0.53641947 | F4: =AVERAGEIFS(Calculated_Ratios!G:G, Calculated_Ratios!B:B, A4) -> 0.040435123 | G4: =AVERAGEIFS(Calculated_Ratios!H:H, Calculated_Ratios!B:B, A4) -> 0.37030059 | H4: =AVERAGEIFS(Calculated_Ratios!I:I, Calculated_Ratios!B:B, A4) -> 7.3294119
A5: 2021 | B5: =AVERAGEIFS(Calculated_Ratios!C:C, Calculated_Ratios!B:B, A5) -> 0.025590048 | C5: =AVERAGEIFS(Calculated_Ratios!D:D, Calculated_Ratios!B:B, A5) -> 0.18648038 | D5: =AVERAGEIFS(Calculated_Ratios!E:E, Calculated_Ratios!B:B, A5) -> 0.056400081 | E5: =AVERAGEIFS(Calculated_Ratios!F:F, Calculated_Ratios!B:B, A5) -> 0.46970866 | F5: =AVERAGEIFS(Calculated_Ratios!G:G, Calculated_Ratios!B:B, A5) -> 0.02799913 | G5: =AVERAGEIFS(Calculated_Ratios!H:H, Calculated_Ratios!B:B, A5) -> 0.37702836 | H5: =AVERAGEIFS(Calculated_Ratios!I:I, Calculated_Ratios!B:B, A5) -> 7.1010796
A6: 2022 | B6: =AVERAGEIFS(Calculated_Ratios!C:C, Calculated_Ratios!B:B, A6) -> 0.013574671 | C6: =AVERAGEIFS(Calculated_Ratios!D:D, Calculated_Ratios!B:B, A6) -> 0.14779848 | D6: =AVERAGEIFS(Calculated_Ratios!E:E, Calculated_Ratios!B:B, A6) -> 0.055551019 | E6: =AVERAGEIFS(Calculated_Ratios!F:F, Calculated_Ratios!B:B, A6) -> 0.20717421 | F6: =AVERAGEIFS(Calculated_Ratios!G:G, Calculated_Ratios!B:B, A6) -> 0.056194051 | G6: =AVERAGEIFS(Calculated_Ratios!H:H, Calculated_Ratios!B:B, A6) -> 0.32789746 | H6: =AVERAGEIFS(Calculated_Ratios!I:I, Calculated_Ratios!B:B, A6) -> 6.7294493
A7: 2023 | B7: =AVERAGEIFS(Calculated_Ratios!C:C, Calculated_Ratios!B:B, A7) -> 0.024598115 | C7: =AVERAGEIFS(Calculated_Ratios!D:D, Calculated_Ratios!B:B, A7) -> 0.17496488 | D7: =AVERAGEIFS(Calculated_Ratios!E:E, Calculated_Ratios!B:B, A7) -> 0.055331573 | E7: =AVERAGEIFS(Calculated_Ratios!F:F, Calculated_Ratios!B:B, A7) -> 0.51524641 | F7: =AVERAGEIFS(Calculated_Ratios!G:G, Calculated_Ratios!B:B, A7) -> 0.068905189 | G7: =AVERAGEIFS(Calculated_Ratios!H:H, Calculated_Ratios!B:B, A7) -> 0.34558624 | H7: =AVERAGEIFS(Calculated_Ratios!I:I, Calculated_Ratios!B:B, A7) -> 6.101366
A8: 2024 | B8: =AVERAGEIFS(Calculated_Ratios!C:C, Calculated_Ratios!B:B, A8) -> 0.030809848 | C8: =AVERAGEIFS(Calculated_Ratios!D:D, Calculated_Ratios!B:B, A8) -> 0.19728833 | D8: =AVERAGEIFS(Calculated_Ratios!E:E, Calculated_Ratios!B:B, A8) -> 0.052962939 | E8: =AVERAGEIFS(Calculated_Ratios!F:F, Calculated_Ratios!B:B, A8) -> 0.42843197 | F8: =AVERAGEIFS(Calculated_Ratios!G:G, Calculated_Ratios!B:B, A8) -> 0.13434616 | G8: =AVERAGEIFS(Calculated_Ratios!H:H, Calculated_Ratios!B:B, A8) -> 0.35125127 | H8: =AVERAGEIFS(Calculated_Ratios!I:I, Calculated_Ratios!B:B, A8) -> 5.9889832

Sheet ROA Trend
A3: Average of ROA | B3: Column Labels
A4: Row Labels | B4: Basis | C4: BoG | D4: Credo | E4: TBC | F4: VTB | G4: Grand Total
A5: 2018 | B5: 0.027961426 | C5: 0.025311241 | D5: 0.02902434 | E5: 0.03052474 | F5: 0.016608555 | G5: 0.025886061
A6: 2019 | B6: 0.023800157 | C6: 0.03122903 | D6: 0.03306256 | E6: 0.032327783 | F6: 0.017819169 | G6: 0.02764774
A7: 2020 | B7: 0.01285053 | C7: 0.015289913 | D7: 0.0091995276 | E7: 0.016570701 | F7: 0.013977968 | G7: 0.013577728
A8: 2021 | B8: 0.01929821 | C8: 0.033110126 | D8: 0.023643814 | E8: 0.036303734 | F8: 0.015594359 | G8: 0.025590048
A9: 2022 | B9: 0.028927203 | C9: 0.038503291 | D9: 0.02293485 | E9: 0.039072136 | F9: -0.061564123 | G9: 0.013574671
A10: 2023 | B10: 0.022626365 | C10: 0.044634971 | D10: 0.017637757 | E10: 0.037239776 | F10: 0.00085170442 | G10: 0.024598115
A11: 2024 | B11: 0.0227869 | C11: 0.052015563 | D11: 0.024772791 | E11: 0.035857124 | F11: 0.018616862 | G11: 0.030809848
A12: Grand Total | B12: 0.022607256 | C12: 0.034299162 | D12: 0.02289652 | E12: 0.032556571 | F12: 0.0031292134 | G12: 0.023097744
A16: Row Labels | B16: Basis | C16: BoG | D16: Credo | E16: TBC | F16: VTB | G16: Industry
A17: 2018 | B17: 0.027961426 | C17: 0.025311241 | D17: 0.02902434 | E17: 0.03052474 | F17: 0.016608555 | G17: 0.0259
A18: 2019 | B18: 0.023800157 | C18: 0.03122903 | D18: 0.03306256 | E18: 0.032327783 | F18: 0.017819169 | G18: 0.0276
A19: 2020 | B19: 0.01285053 | C19: 0.015289913 | D19: 0.0091995276 | E19: 0.016570701 | F19: 0.013977968 | G19: 0.0136
A20: 2021 | B20: 0.01929821 | C20: 0.033110126 | D20: 0.023643814 | E20: 0.036303734 | F20: 0.015594359 | G20: 0.0256
A21: 2022 | B21: 0.028927203 | C21: 0.038503291 | D21: 0.02293485 | E21: 0.039072136 | F21: -0.061564123 | G21: 0.0136
A22: 2023 | B22: 0.022626365 | C22: 0.044634971 | D22: 0.017637757 | E22: 0.037239776 | F22: 0.00085170442 | G22: 0.0246
A23: 2024 | B23: 0.0227869 | C23: 0.052015563 | D23: 0.024772791 | E23: 0.035857124 | F23: 0.018616862 | G23: 0.0308
A27: Row Labels | B27: Basis | C27: BoG | D27: Credo | E27: TBC | F27: VTB | G27: Industry
A28: 2018 | B28: 0.16107986 | C28: 0.21383982 | D28: 0.16156225 | E28: 0.21883181 | F28: 0.11162034 | G28: 0.1734
A29: 2019 | B29: 0.14001861 | C29: 0.26934336 | D29: 0.20937395 | E29: 0.23503344 | F29: 0.11047437 | G29: 0.1928
A30: 2020 | B30: 0.081754786 | C30: 0.13426121 | D30: 0.068650696 | E30: 0.12579893 | F30: 0.09015771 | G30: 0.1001
A31: 2021 | B31: 0.11685989 | C31: 0.26854695 | D31: 0.18925168 | E31: 0.26259008 | F31: 0.095153324 | G31: 0.1865
A32: 2022 | B32: 0.18378441 | C32: 0.33980938 | D32: 0.18498281 | E32: 0.26046172 | F32: -0.23004593 | G32: 0.1478
A33: 2023 | B33: 0.15777383 | C33: 0.32374107 | D33: 0.14375715 | E33: 0.24830679 | F33: 0.001245551 | G33: 0.175
A34: 2024 | B34: 0.15162363 | C34: 0.36457034 | D34: 0.20044586 | E34: 0.24400125 | F34: 0.025800593 | G34: 0.1973

Sheet Benchmark Difference Table
A1: Bank | B1: Year | C1: ROA | D1: Industry ROA | E1: ROA Difference | F1: ROE | G1: Industry ROE | H1: ROE Difference | I1: NIM_approx | J1: Industry NIM | K1: NIM Difference | L1: CIR | M1: Industry CIR | N1: CIR Difference | O1: NPL | P1: Industry NPL | Q1: NPL Difference | R1: Loan-to-Asset Ratio | S1: Industry Loan-to-Asset | T1: Loan-to-Asset Difference | U1: Equity Multiplier | V1: Industry Equity Multiplier | W1: Difference Equity Multiplier
A2: BoG | B2: 2018 | C2: =(Raw_Data!C2)/((Raw_Data!D2+Raw_Data!E2)/2) -> 0.025311241 | D2: 0.0259 | E2: =C2-D2 -> -0.00058875882 | F2: 0.21383982 | G2: 0.17338681 | H2: =F2-G2 -> 0.040453004 | I2: 0.053900371 | J2: 0.067418097 | K2: =I2-J2 -> -0.013517726 | L2: 0.35951998 | M2: 0.47914859 | N2: =L2-M2 -> -0.11962861 | O2: 0.03562367 | P2: 0.029540774 | Q2: =O2-P2 -> 0.0060828961 | R2: 0.34744473 | S2: 0.37976 | T2: =R2-S2 -> -0.032315272 | U2: 8.4484129 | V2: 6.7330585 | W2: =U2-V2 -> 1.7153544
A3: BoG | B3: 2019 | C3: =(Raw_Data!C3)/((Raw_Data!D3+Raw_Data!E3)/2) -> 0.03122903 | D3: 0.0276 | E3: =C3-D3 -> 0.0036290295 | F3: 0.26934336 | G3: 0.19284874 | H3: =F3-G3 -> 0.07649462 | I3: 0.047710752 | J3: 0.061215422 | K3: =I3-J3 -> -0.01350467 | L3: 0.37174504 | M3: 0.49458332 | N3: =L3-M3 -> -0.12283828 | O3: 0.021932961 | P3: 0.029268537 | Q3: =O3-P3 -> -0.0073355754 | R3: 0.36006522 | S3: 0.37657148 | T3: =R3-S3 -> -0.01650626 | U3: 8.6247753 | V3: 6.8621206 | W3: =U3-V3 -> 1.7626547
A4: BoG | B4: 2020 | C4: =(Raw_Data!C4)/((Raw_Data!D4+Raw_Data!E4)/2) -> 0.015289913 | D4: 0.0136 | E4: =C4-D4 -> 0.0016899132 | F4: 0.13426121 | G4: 0.10012467 | H4: =F4-G4 -> 0.034136544 | I4: 0.038162476 | J4: 0.050159718 | K4: =I4-J4 -> -0.011997243 | L4: 0.37568995 | M4: 0.53641947 | N4: =L4-M4 -> -0.16072952 | O4: 0.039717727 | P4: 0.040435123 | Q4: =O4-P4 -> -0.00071739576 | R4: 0.35684428 | S4: 0.37030059 | T4: =R4-S4 -> -0.01345631 | U4: 8.7810315 | V4: 7.3294119 | W4: =U4-V4 -> 1.4516196
A5: BoG | B5: 2021 | C5: =(Raw_Data!C5)/((Raw_Data!D5+Raw_Data!E5)/2) -> 0.033110126 | D5: 0.0256 | E5: =C5-D5 -> 0.007510126 | F5: 0.26854695 | G5: 0.18648038 | H5: =F5-G5 -> 0.082066565 | I5: 0.041882622 | J5: 0.056400081 | K5: =I5-J5 -> -0.014517459 | L5: 0.35354852 | M5: 0.46970866 | N5: =L5-M5 -> -0.11616014 | O5: 0.025781325 | P5: 0.02799913 | Q5: =O5-P5 -> -0.0022178047 | R5: 0.36236605 | S5: 0.37702836 | T5: =R5-S5 -> -0.014662308 | U5: 8.1107196 | V5: 7.1010796 | W5: =U5-V5 -> 1.0096401
A6: BoG | B6: 2022 | C6: =(Raw_Data!C6)/((Raw_Data!D6+Raw_Data!E6)/2) -> 0.038503291 | D6: 0.0136 | E6: =C6-D6 -> 0.024903291 | F6: 0.33980938 | G6: 0.14779848 | H6: =F6-G6 -> 0.19201091 | I6: 0.045590935 | J6: 0.055551019 | K6: =I6-J6 -> -0.0099600837 | L6: 0.30117531 | M6: 0.20717421 | N6: =L6-M6 -> 0.094001097 | O6: 0.027632743 | P6: 0.056194051 | Q6: =O6-P6 -> -0.028561307 | R6: 0.33145079 | S6: 0.32789746 | T6: =R6-S6 -> 0.003553336 | U6: 8.8254632 | V6: 6.7294493 | W6: =U6-V6 -> 2.0960139
A7: BoG | B7: 2023 | C7: =(Raw_Data!C7)/((Raw_Data!D7+Raw_Data!E7)/2) -> 0.044634971 | D7: 0.0246 | E7: =C7-D7 -> 0.020034971 | F7: 0.32374107 | G7: 0.17496488 | H7: =F7-G7 -> 0.14877619 | I7: 0.053077945 | J7: 0.055331573 | K7: =I7-J7 -> -0.0022536276 | L7: 0.28141708 | M7: 0.51524641 | N7: =L7-M7 -> -0.23382934 | O7: 0.022148183 | P7: 0.068905189 | Q7: =O7-P7 -> -0.046757005 | R7: 0.34322798 | S7: 0.34558624 | T7: =R7-S7 -> -0.0023582572 | U7: 7.2530812 | V7: 6.101366 | W7: =U7-V7 -> 1.1517152
A8: BoG | B8: 2024 | C8: =(Raw_Data!C8)/((Raw_Data!D8+Raw_Data!E8)/2) -> 0.052015563 | D8: 0.0308 | E8: =C8-D8 -> 0.021215563 | F8: 0.36457034 | G8: 0.19728833 | H8: =F8-G8 -> 0.16728201 | I8: 0.05215277 | J8: 0.052962939 | K8: =I8-J8 -> -0.00081016994 | L8: 0.28978421 | M8: 0.42843197 | N8: =L8-M8 -> -0.13864777 | O8: 0.023015685 | P8: 0.13434616 | Q8: =O8-P8 -> -0.11133047 | R8: 0.34274342 | S8: 0.35125127 | T8: =R8-S8 -> -0.0085078481 | U8: 7.0088705 | V8: 5.9889832 | W8: =U8-V8 -> 1.0198873
A9: TBC | B9: 2018 | C9: =(Raw_Data!C9)/((Raw_Data!D9+Raw_Data!E9)/2) -> 0.03052474 | D9: 0.0259 | E9: =C9-D9 -> 0.0046247402 | F9: 0.21883181 | G9: 0.17338681 | H9: =F9-G9 -> 0.045444994 | I9: 0.054283597 | J9: 0.067418097 | K9: =I9-J9 -> -0.0131345 | L9: 0.37138738 | M9: 0.47914859 | N9: =L9-M9 -> -0.10776121 | O9: 0.030999996 | P9: 0.029540774 | Q9: =O9-P9 -> 0.0014592218 | R9: 0.3653593 | S9: 0.37976 | T9: =R9-S9 -> -0.014400699 | U9: 7.1689982 | V9: 6.7330585 | W9: =U9-V9 -> 0.4359397
A10: TBC | B10: 2019 | C10: =(Raw_Data!C10)/((Raw_Data!D10+Raw_Data!E10)/2) -> 0.032327783 | D10: 0.0276 | E10: =C10-D10 -> 0.0047277835 | F10: 0.23503344 | G10: 0.19284874 | H10: =F10-G10 -> 0.042184691 | I10: 0.046993579 | J10: 0.061215422 | K10: =I10-J10 -> -0.014221843 | L10: 0.37721121 | M10: 0.49458332 | N10: =L10-M10 -> -0.11737211 | O10: 0.027000017 | P10: 0.029268537 | Q10: =O10-P10 -> -0.0022685196 | R10: 0.3750634 | S10: 0.37657148 | T10: =R10-S10 -> -0.0015080867 | U10: 7.2703232 | V10: 6.8621206 | W10: =U10-V10 -> 0.40820262
A11: TBC | B11: 2020 | C11: =(Raw_Data!C11)/((Raw_Data!D11+Raw_Data!E11)/2) -> 0.016570701 | D11: 0.0136 | E11: =C11-D11 -> 0.0029707011 | F11: 0.12579893 | G11: 0.10012467 | H11: =F11-G11 -> 0.02567426 | I11: 0.040667594 | J11: 0.050159718 | K11: =I11-J11 -> -0.0094921244 | L11: 0.35092098 | M11: 0.53641947 | N11: =L11-M11 -> -0.18549849 | O11: 0.046999987 | P11: 0.040435123 | Q11: =O11-P11 -> 0.0065648638 | R11: 0.37342583 | S11: 0.37030059 | T11: =R11-S11 -> 0.0031252352 | U11: 7.5916477 | V11: 7.3294119 | W11: =U11-V11 -> 0.26223585
A12: TBC | B12: 2021 | C12: =(Raw_Data!C12)/((Raw_Data!D12+Raw_Data!E12)/2) -> 0.036303734 | D12: 0.0256 | E12: =C12-D12 -> 0.010703734 | F12: 0.26259008 | G12: 0.18648038 | H12: =F12-G12 -> 0.076109693 | I12: 0.042886508 | J12: 0.056400081 | K12: =I12-J12 -> -0.013513573 | L12: 0.32548136 | M12: 0.46970866 | N12: =L12-M12 -> -0.14422729 | O12: 0.023999984 | P12: 0.02799913 | Q12: =O12-P12 -> -0.0039991458 | R12: 0.36509712 | S12: 0.37702836 | T12: =R12-S12 -> -0.011931241 | U12: 7.2331424 | V12: 7.1010796 | W12: =U12-V12 -> 0.13206283
A13: TBC | B13: 2022 | C13: =(Raw_Data!C13)/((Raw_Data!D13+Raw_Data!E13)/2) -> 0.039072136 | D13: 0.0136 | E13: =C13-D13 -> 0.025472136 | F13: 0.26046172 | G13: 0.14779848 | H13: =F13-G13 -> 0.11266324 | I13: 0.047474893 | J13: 0.055551019 | K13: =I13-J13 -> -0.0080761252 | L13: 0.2882168 | M13: 0.20717421 | N13: =L13-M13 -> 0.081042587 | O13: 0.021999996 | P13: 0.056194051 | Q13: =O13-P13 -> -0.034194055 | R13: 0.34099255 | S13: 0.32789746 | T13: =R13-S13 -> 0.013095095 | U13: 6.6661756 | V13: 6.7294493 | W13: =U13-V13 -> -0.063273701
... A36: VTB | B36: 2024 | C36: =(Raw_Data!C36)/((Raw_Data!D36+Raw_Data!E36)/2) -> 0.018616862 | D36: 0.0308 | E36: =C36-D36 -> -0.012183138 | F36: 0.025800593 | G36: 0.19728833 | H36: =F36-G36 -> -0.17148774 | I36: 0.016710903 | J36: 0.052962939 | K36: =I36-J36 -> -0.036252037 | L36: 0.46653295 | M36: 0.42843197 | N36: =L36-M36 -> 0.038100976 | O36: 0.58546943 | P36: 0.13434616 | Q36: =O36-P36 -> 0.45112327 | R36: 0.21581172 | S36: 0.35125127 | T36: =R36-S36 -> -0.13543956 | U36: 1.3858723 | V36: 5.9889832 | W36: =U36-V36 -> -4.6031109

Sheet Industry Comparison Charts
A1: Row Labels | B1: Basis | C1: BoG | D1: Credo | E1: TBC | F1: VTB | G1: Industry | H1: ROA
A2: 2018 | B2: 0.027961426 | C2: 0.025311241 | D2: 0.02902434 | E2: 0.03052474 | F2: 0.016608555 | G2: 0.0259
A3: 2019 | B3: 0.023800157 | C3: 0.03122903 | D3: 0.03306256 | E3: 0.032327783 | F3: 0.017819169 | G3: 0.0276
A4: 2020 | B4: 0.01285053 | C4: 0.015289913 | D4: 0.0091995276 | E4: 0.016570701 | F4: 0.013977968 | G4: 0.0136
A5: 2021 | B5: 0.01929821 | C5: 0.033110126 | D5: 0.023643814 | E5: 0.036303734 | F5: 0.015594359 | G5: 0.0256
A6: 2022 | B6: 0.028927203 | C6: 0.038503291 | D6: 0.02293485 | E6: 0.039072136 | F6: -0.061564123 | G6: 0.0136
A7: 2023 | B7: 0.022626365 | C7: 0.044634971 | D7: 0.017637757 | E7: 0.037239776 | F7: 0.00085170442 | G7: 0.0246
A8: 2024 | B8: 0.0227869 | C8: 0.052015563 | D8: 0.024772791 | E8: 0.035857124 | F8: 0.018616862 | G8: 0.0308
A12: Row Labels | B12: Basis | C12: BoG | D12: Credo | E12: TBC | F12: VTB | G12: Industry | H12: ROE
A13: 2018 | B13: 0.16107986 | C13: 0.21383982 | D13: 0.16156225 | E13: 0.21883181 | F13: 0.11162034 | G13: 0.1734
A14: 2019 | B14: 0.14001861 | C14: 0.26934336 | D14: 0.20937395 | E14: 0.23503344 | F14: 0.11047437 | G14: 0.1928
A15: 2020 | B15: 0.081754786 | C15: 0.13426121 | D15: 0.068650696 | E15: 0.12579893 | F15: 0.09015771 | G15: 0.1001
A16: 2021 | B16: 0.11685989 | C16: 0.26854695 | D16: 0.18925168 | E16: 0.26259008 | F16: 0.095153324 | G16: 0.1865
A17: 2022 | B17: 0.18378441 | C17: 0.33980938 | D17: 0.18498281 | E17: 0.26046172 | F17: -0.23004593 | G17: 0.1478
A18: 2023 | B18: 0.15777383 | C18: 0.32374107 | D18: 0.14375715 | E18: 0.24830679 | F18: 0.001245551 | G18: 0.175
A19: 2024 | B19: 0.15162363 | C19: 0.36457034 | D19: 0.20044586 | E19: 0.24400125 | F19: 0.025800593 | G19: 0.1973
A23: Row Labels | B23: Basis | C23: BoG | D23: Credo | E23: TBC | F23: VTB | G23: Industry | H23: NIM
A24: 2018 | B24: 0.041777184 | C24: 0.053900371 | D24: 0.14543076 | E24: 0.054283597 | F24: 0.041698573 | G24: 0.0674
A25: 2019 | B25: 0.037897767 | C25: 0.047710752 | D25: 0.13488727 | E25: 0.046993579 | F25: 0.038587737 | G25: 0.0612
A26: 2020 | B26: 0.028858913 | C26: 0.038162476 | D26: 0.10641391 | E26: 0.040667594 | F26: 0.036695697 | G26: 0.0502
A27: 2021 | B27: 0.033972572 | C27: 0.041882622 | D27: 0.1224519 | E27: 0.042886508 | F27: 0.040806806 | G27: 0.0564
A28: 2022 | B28: 0.049156401 | C28: 0.045590935 | D28: 0.11160771 | E28: 0.047474893 | F28: 0.023925149 | G28: 0.0556
A29: 2023 | B29: 0.040203918 | C29: 0.053077945 | D29: 0.10901717 | E29: 0.049770129 | F29: 0.024588707 | G29: 0.0553
A30: 2024 | B30: 0.04090632 | C30: 0.05215277 | D30: 0.10921224 | E30: 0.045832462 | F30: 0.016710903 | G30: 0.053
A34: Row Labels | B34: Basis | C34: BoG | D34: Credo | E34: TBC | F34: VTB | G34: Industry | H34: CIR
A35: 2018 | B35: 0.37268495 | C35: 0.35951998 | D35: 0.67948707 | E35: 0.37138738 | F35: 0.61266358 | G35: 0.4791
A36: 2019 | B36: 0.43840541 | C36: 0.37174504 | D36: 0.6308682 | E36: 0.37721121 | F36: 0.65468674 | G36: 0.4946
A37: 2020 | B37: 0.46910666 | C37: 0.37568995 | D37: 0.66233793 | E37: 0.35092098 | F37: 0.82404181 | G37: 0.5364
A38: 2021 | B38: 0.49914505 | C38: 0.35354852 | D38: 0.58775125 | E38: 0.32548136 | F38: 0.58261711 | G38: 0.4697
A39: 2022 | B39: 0.47664688 | C39: 0.30117531 | D39: 0.58438311 | E39: 0.2882168 | F39: -0.61455105 | G39: 0.2072
A40: 2023 | B40: 0.47628707 | C40: 0.28141708 | D40: 0.61014925 | E40: 0.319759 | F40: 0.88861967 | G40: 0.5152
A41: 2024 | B41: 0.49179298 | C41: 0.28978421 | D41: 0.56570133 | E41: 0.3283484 | F41: 0.46653295 | G41: 0.4284
A45: Row Labels | B45: Basis | C45: BoG | D45: Credo | E45: TBC | F45: VTB | G45: Industry | H45: NPL
A46: 2018 | B46: 0.044373349 | C46: 0.03562367 | D46: 0.0045295677 | E46: 0.030999996 | F46: 0.032177288 | G46: 0.0295
A47: 2019 | B47: 0.053545029 | C47: 0.021932961 | D47: 0.0044341416 | E47: 0.027000017 | F47: 0.039430534 | G47: 0.0293
A48: 2020 | B48: 0.075323385 | C48: 0.039717727 | D48: 0.011491233 | E48: 0.046999987 | F48: 0.028643282 | G48: 0.0404
A49: 2021 | B49: 0.047427451 | C49: 0.025781325 | D49: 0.016477375 | E49: 0.023999984 | F49: 0.026309514 | G49: 0.028
A50: 2022 | B50: 0.039117665 | C50: 0.027632743 | D50: 0.0097720633 | E50: 0.021999996 | F50: 0.18244779 | G50: 0.0562
A51: 2023 | B51: 0.037015405 | C51: 0.022148183 | D51: 0.0097530938 | E51: 0.020000001 | F51: 0.25560926 | G51: 0.0689
A52: 2024 | B52: 0.033206561 | C52: 0.023015685 | D52: 0.0080391132 | E52: 0.022000002 | F52: 0.58546943 | G52: 0.1343
...

Sheet Economic Phase Analysis
A1: ROA
A2: Bank | B2: Pre-COVID Avg ROA | C2: COVID 2020 ROA | D2: Recovery 2021-22 Avg ROA | E2: Post-2022 Avg ROA | F2: 7-Yr Avg | G2: Best Phase | H2: Worst Phase
A3: BoG | B3: =(Calculated_Ratios!C2+Calculated_Ratios!C3)/2 -> 0.028270135 | C3: =Calculated_Ratios!C4 -> 0.015289913 | D3: =(Calculated_Ratios!C5+Calculated_Ratios!C6)/2 -> 0.035806709 | E3: =(Calculated_Ratios!C7+Calculated_Ratios!C8)/2 -> 0.048325267 | F3: =AVERAGE(Calculated_Ratios!C2:C8) -> 0.034299162 | G3: Post-2022 | H3: COVID 2020
A4: TBC | B4: =(Calculated_Ratios!C9+Calculated_Ratios!C10)/2 -> 0.031426262 | C4: =Calculated_Ratios!C11 -> 0.016570701 | D4: =(Calculated_Ratios!C12+Calculated_Ratios!C13)/2 -> 0.037687935 | E4: =(Calculated_Ratios!C14+Calculated_Ratios!C15)/2 -> 0.03654845 | F4: =AVERAGE(Calculated_Ratios!C9:C15) -> 0.032556571 | G4: Recovery 2021-22 | H4: COVID 2020
A5: Basis | B5: =(Calculated_Ratios!C16+Calculated_Ratios!C17)/2 -> 0.025880791 | C5: =Calculated_Ratios!C18 -> 0.01285053 | D5: =(Calculated_Ratios!C19+Calculated_Ratios!C20)/2 -> 0.024112706 | E5: =(Calculated_Ratios!C21+Calculated_Ratios!C22)/2 -> 0.022706632 | F5: =AVERAGE(Calculated_Ratios!C16:C22) -> 0.022607256 | G5: Recovery 2021-22 | H5: COVID 2020
A6: Credo | B6: =(Calculated_Ratios!C23+Calculated_Ratios!C24)/2 -> 0.03104345 | C6: =Calculated_Ratios!C25 -> 0.0091995276 | D6: =(Calculated_Ratios!C26+Calculated_Ratios!C27)/2 -> 0.023289332 | E6: =(Calculated_Ratios!C28+Calculated_Ratios!C29)/2 -> 0.021205274 | F6: =AVERAGE(Calculated_Ratios!C23:C29) -> 0.02289652 | G6: Pre-COVID | H6: COVID 2020
A7: VTB | B7: =(Calculated_Ratios!C30+Calculated_Ratios!C31)/2 -> 0.017213862 | C7: =Calculated_Ratios!C32 -> 0.013977968 | D7: =(Calculated_Ratios!C33+Calculated_Ratios!C34)/2 -> -0.022984882 | E7: =(Calculated_Ratios!C35+Calculated_Ratios!C36)/2 -> 0.0097342834 | F7: =AVERAGE(Calculated_Ratios!C30:C36) -> 0.0031292134 | G7: Pre-COVID | H7: Recovery 2021-2022
A8: Industry | B8: =('Industry Benchmark Analysis'!B2+'Industry Benchmark Analysis'!B3)/2 -> 0.0267669 | C8: ='Industry Benchmark Analysis'!B4 -> 0.013577728 | D8: =('Industry Benchmark Analysis'!B5+'Industry Benchmark Analysis'!B6)/2 -> 0.01958236 | E8: =('Industry Benchmark Analysis'!B7+'Industry Benchmark Analysis'!B8)/2 -> 0.027703981 | F8: =AVERAGE('Industry Benchmark Analysis'!B2:B8) -> 0.023097744 | G8: Post-2022 | H8: COVID 2020
A10: ROE
A11: Bank | B11: Pre-COVID Avg ROE | C11: COVID 2020 ROE | D11: Recovery 2021-22 Avg ROE | E11: Post-2022 Avg ROE | F11: 7-Yr Avg | G11: Best Phase | H11: Worst Phase
A12: BoG | B12: =(Calculated_Ratios!D2+Calculated_Ratios!D3)/2 -> 0.24159159 | C12: =Calculated_Ratios!D4 -> 0.13426121 | D12: =(Calculated_Ratios!D5+Calculated_Ratios!D6)/2 -> 0.30417817 | E12: =(Calculated_Ratios!D7+Calculated_Ratios!D8)/2 -> 0.34415571 | F12: =AVERAGE(Calculated_Ratios!D2:D8) -> 0.27344459 | G12: Post-2022 | H12: COVID 2020
A13: TBC | B13: =(Calculated_Ratios!D9+Calculated_Ratios!D10)/2 -> 0.22693262 | C13: =Calculated_Ratios!D11 -> 0.12579893 | D13: =(Calculated_Ratios!D12+Calculated_Ratios!D13)/2 -> 0.2615259 | E13: =(Calculated_Ratios!D14+Calculated_Ratios!D15)/2 -> 0.24615402 | F13: =AVERAGE(Calculated_Ratios!D9:D15) -> 0.22786057 | G13: Recovery 2021-2022 | H13: COVID 2020
A14: Basis | B14: =(Calculated_Ratios!D16+Calculated_Ratios!D17)/2 -> 0.15054923 | C14: =Calculated_Ratios!D18 -> 0.081754786 | D14: =(Calculated_Ratios!D19+Calculated_Ratios!C20)/2 -> 0.072893545 | E14: =(Calculated_Ratios!D21+Calculated_Ratios!D22)/2 -> 0.15469873 | F14: =AVERAGE(Calculated_Ratios!D16:D22) -> 0.14184214 | G14: Post-2022 | H14: Recovery 2021-2022
A15: Credo | B15: =(Calculated_Ratios!D23+Calculated_Ratios!D24)/2 -> 0.1854681 | C15: =Calculated_Ratios!D25 -> 0.068650696 | D15: =(Calculated_Ratios!D26+Calculated_Ratios!D27)/2 -> 0.18711724 | E15: =(Calculated_Ratios!C28+Calculated_Ratios!C29)/2 -> 0.021205274 | F15: =AVERAGE(Calculated_Ratios!D23:D29) -> 0.16543206 | G15: Recovery 2021-2022 | H15: Post-2022
A16: VTB | B16: =(Calculated_Ratios!D30+Calculated_Ratios!D31)/2 -> 0.11104735 | C16: =Calculated_Ratios!D32 -> 0.09015771 | D16: =(Calculated_Ratios!D33+Calculated_Ratios!D34)/2 -> -0.067446305 | E16: =(Calculated_Ratios!D35+Calculated_Ratios!D36)/2 -> 0.013523072 | F16: =AVERAGE(Calculated_Ratios!D30:D36) -> 0.02920085 | G16: Pre-COVID | H16: Recovery 2021-2022
A17: Industry | B17: =('Industry Benchmark Analysis'!C2+'Industry Benchmark Analysis'!C3)/2 -> 0.18311778 | C17: ='Industry Benchmark Analysis'!C4 -> 0.10012467 | D17: =('Industry Benchmark Analysis'!C5+'Industry Benchmark Analysis'!C6)/2 -> 0.16713943 | E17: =('Industry Benchmark Analysis'!C7+'Industry Benchmark Analysis'!C8)/2 -> 0.18612661 | F17: =AVERAGE('Industry Benchmark Analysis'!C2:C8) -> 0.16755604 | G17: Pre-COVID | H17: COVID 2020
A19: NIM
A20: Bank | B20: Pre-COVID Avg NIM | C20: COVID 2020 NIM | D20: Recovery 2021-22 Avg NIM | E20: Post-2022 Avg NIM | F20: 7-Yr Avg | G20: Best Phase | H20: Worst Phase
A21: BoG | B21: =(Calculated_Ratios!E2+Calculated_Ratios!E3)/2 -> 0.050805561 | C21: =Calculated_Ratios!E4 -> 0.038162476 | D21: =(Calculated_Ratios!E5+Calculated_Ratios!E6)/2 -> 0.043736778 | E21: =(Calculated_Ratios!E7+Calculated_Ratios!E8)/2 -> 0.052615357 | F21: =AVERAGE(Calculated_Ratios!E2:E8) -> 0.047496839 | G21: Post-2022 | H21: COVID 2020
A22: TBC | B22: =(Calculated_Ratios!E9+Calculated_Ratios!E10)/2 -> 0.050638588 | C22: =Calculated_Ratios!E11 -> 0.040667594 | D22: =(Calculated_Ratios!E12+Calculated_Ratios!E13)/2 -> 0.045180701 | E22: =(Calculated_Ratios!E14+Calculated_Ratios!E15)/2 -> 0.047801295 | F22: =AVERAGE(Calculated_Ratios!D9:D15) -> 0.22786057 | G22: Pre-COVID | H22: COVID 2020
A23: Basis | B23: =(Calculated_Ratios!E16+Calculated_Ratios!E17)/2 -> 0.039837475 | C23: =Calculated_Ratios!E18 -> 0.028858913 | D23: =(Calculated_Ratios!E19+Calculated_Ratios!E20)/2 -> 0.041564486 | E23: =(Calculated_Ratios!E21+Calculated_Ratios!E22)/2 -> 0.040555119 | F23: =AVERAGE(Calculated_Ratios!D16:D22) -> 0.14184214 | G23: Recovery 2021-2022 | H23: COVID 2020
A24: Credo | B24: =(Calculated_Ratios!E23+Calculated_Ratios!E24)/2 -> 0.14015902 | C24: =Calculated_Ratios!E25 -> 0.10641391 | D24: =(Calculated_Ratios!E26+Calculated_Ratios!E27)/2 -> 0.11702981 | E24: =(Calculated_Ratios!E28+Calculated_Ratios!E29)/2 -> 0.1091147 | F24: =AVERAGE(Calculated_Ratios!D23:D29) -> 0.16543206 | G24: Pre-COVID | H24: COVID 2020
A25: VTB | B25: =(Calculated_Ratios!E30+Calculated_Ratios!E31)/2 -> 0.040143155 | C25: =Calculated_Ratios!E32 -> 0.036695697 | D25: =(Calculated_Ratios!E33+Calculated_Ratios!E34)/2 -> 0.032365978 | E25: =(Calculated_Ratios!E35+Calculated_Ratios!E36)/2 -> 0.020649805 | F25: =AVERAGE(Calculated_Ratios!D30:D36) -> 0.02920085 | G25: Pre-COVID | H25: Post-2022
A26: Industry | B26: =('Industry Benchmark Analysis'!D2+'Industry Benchmark Analysis'!D3)/2 -> 0.064316759 | C26: ='Industry Benchmark Analysis'!D4 -> 0.050159718 | D26: =('Industry Benchmark Analysis'!D5+'Industry Benchmark Analysis'!D6)/2 -> 0.05597555 | E26: =('Industry Benchmark Analysis'!D7+'Industry Benchmark Analysis'!D8)/2 -> 0.054147256 | F26: =AVERAGE('Industry Benchmark Analysis'!D2:D8) -> 0.05700555 | G26: Pre-COVID | H26: COVID 2020
A28: CIR
A29: Bank | B29: Pre-COVID Avg CIR | C29: COVID 2020 CIR | D29: Recovery 2021-22 Avg CIR | E29: Post- Avg CIR | F29: 7-Yr Avg | G29: Best Phase | H29: Worst Phase
A30: BoG | B30: =(Calculated_Ratios!F2+Calculated_Ratios!F3)/2 -> 0.36563251 | C30: =Calculated_Ratios!F4 -> 0.37568995 | D30: =(Calculated_Ratios!F5+Calculated_Ratios!F6)/2 -> 0.32736191 | E30: =(Calculated_Ratios!F7+Calculated_Ratios!F8)/2 -> 0.28560064 | F30: =AVERAGE(Calculated_Ratios!F2:F8) -> 0.33326858 | G30: Post 2022 | H30: COVID 2020
A31: TBC | B31: =(Calculated_Ratios!F9+Calculated_Ratios!F10)/2 -> 0.3742993 | C31: =Calculated_Ratios!F11 -> 0.35092098 | D31: =(Calculated_Ratios!F12+Calculated_Ratios!F13)/2 -> 0.30684908 | E31: =(Calculated_Ratios!F14+Calculated_Ratios!F15)/2 -> 0.3240537 | F31: =AVERAGE(Calculated_Ratios!F9:F15) -> 0.33733216 | G31: Recovery 2021–22 | H31: Pre-COVID 2018–19
A32: Basis | B32: =(Calculated_Ratios!F16+Calculated_Ratios!F17)/2 -> 0.40554518 | C32: =Calculated_Ratios!F18 -> 0.46910666 | D32: =(Calculated_Ratios!F19+Calculated_Ratios!F20)/2 -> 0.48789597 | E32: =(Calculated_Ratios!F21+Calculated_Ratios!F22)/2 -> 0.48404002 | F32: =AVERAGE(Calculated_Ratios!F16:F22) -> 0.46058128 | G32: Pre-COVID 2018–19 | H32: Recovery 2021–22
A33: Credo | B33: =(Calculated_Ratios!F23+Calculated_Ratios!F24)/2 -> 0.65517764 | C33: =Calculated_Ratios!F25 -> 0.66233793 | D33: =(Calculated_Ratios!F26+Calculated_Ratios!F27)/2 -> 0.58606718 | E33: =(Calculated_Ratios!F28+Calculated_Ratios!F29)/2 -> 0.58792529 | F33: =AVERAGE(Calculated_Ratios!F23:F29) -> 0.61723974 | G33: Recovery 2021–22 | H33: COVID 2020
A34: VTB | B34: =(Calculated_Ratios!F30+Calculated_Ratios!F31)/2 -> 0.63367516 | C34: =Calculated_Ratios!F32 -> 0.82404181 | D34: =(Calculated_Ratios!F33+Calculated_Ratios!F34)/2 -> -0.015966972 | E34: =(Calculated_Ratios!F35+Calculated_Ratios!F36)/2 -> 0.67757631 | F34: =AVERAGE(Calculated_Ratios!F30:F36) -> 0.48780154 | G34: Recovery 2021–22 | H34: COVID 2020
A35: Industry | B35: =('Industry Benchmark Analysis'!E2+'Industry Benchmark Analysis'!E3)/2 -> 0.48686596 | C35: ='Industry Benchmark Analysis'!E4 -> 0.53641947 | D35: =('Industry Benchmark Analysis'!E5+'Industry Benchmark Analysis'!E6)/2 -> 0.33844143 | E35: =('Industry Benchmark Analysis'!E7+'Industry Benchmark Analysis'!E8)/2 -> 0.47183919 | F35: =AVERAGE('Industry Benchmark Analysis'!E2:E8) -> 0.44724466 | G35: Recovery 2021–22 | H35: COVID 2020
A37: NPL
A38: Bank | B38: Pre-COVID Avg NPL | C38: COVID 2020 NPL | D38: Recovery 2021-22 Avg NPL | E38: Post-2022 Avg NPL | F38: 7 Yr Avg | G38: Best Phase | H38: Worst Phase
A39: BoG | B39: =(Calculated_Ratios!G2+Calculated_Ratios!G3)/2 -> 0.028778316 | C39: =Calculated_Ratios!G4 -> 0.039717727 | D39: =(Calculated_Ratios!G5+Calculated_Ratios!G6)/2 -> 0.026707034 | E39: =(Calculated_Ratios!G7+Calculated_Ratios!G8)/2 -> 0.022581934 | F39: =AVERAGE(Calculated_Ratios!G2:G8) -> 0.027978899 | G39: Post 2022 | H39: COVID 2020
A40: TBC | B40: =(Calculated_Ratios!G9+Calculated_Ratios!G10)/2 -> 0.029000006 | C40: =Calculated_Ratios!G11 -> 0.046999987 | D40: =(Calculated_Ratios!G12+Calculated_Ratios!G13)/2 -> 0.02299999 | E40: =(Calculated_Ratios!G14+Calculated_Ratios!G15)/2 -> 0.021000001 | F40: =AVERAGE(Calculated_Ratios!G9:G15) -> 0.027571426 | G40: Post 2022 | H40: COVID 2020
A41: Basis | B41: =(Calculated_Ratios!G16+Calculated_Ratios!G17)/2 -> 0.048959189 | C41: =Calculated_Ratios!G18 -> 0.075323385 | D41: =(Calculated_Ratios!G19+Calculated_Ratios!G20)/2 -> 0.043272558 | E41: =(Calculated_Ratios!G21+Calculated_Ratios!G22)/2 -> 0.035110983 | F41: =AVERAGE(Calculated_Ratios!G16:G22) -> 0.047144121 | G41: Post 2022 | H41: COVID 2020
A42: Credo | B42: =(Calculated_Ratios!G23+Calculated_Ratios!G24)/2 -> 0.0044818546 | C42: =Calculated_Ratios!G25 -> 0.011491233 | D42: =(Calculated_Ratios!G26+Calculated_Ratios!G27)/2 -> 0.013124719 | E42: =(Calculated_Ratios!G28+Calculated_Ratios!G29)/2 -> 0.0088961035 | F42: =AVERAGE(Calculated_Ratios!G23:G29) -> 0.0092137982 | G42: Pre-COVID 2018–19 | H42: Recovery 2021–22
A43: VTB | B43: =(Calculated_Ratios!G30+Calculated_Ratios!G31)/2 -> 0.035803911 | C43: =Calculated_Ratios!G32 -> 0.028643282 | D43: =(Calculated_Ratios!G33+Calculated_Ratios!G34)/2 -> 0.10437865 | E43: =(Calculated_Ratios!G35+Calculated_Ratios!G36)/2 -> 0.42053934 | F43: =AVERAGE(Calculated_Ratios!G30:G36) -> 0.16429816 | G43: COVID 2020 | H43: Post 2022
A44: Industry | B44: =('Industry Benchmark Analysis'!F2+'Industry Benchmark Analysis'!F3)/2 -> 0.029404655 | C44: ='Industry Benchmark Analysis'!F4 -> 0.040435123 | D44: =('Industry Benchmark Analysis'!F5+'Industry Benchmark Analysis'!F6)/2 -> 0.04209659 | E44: =('Industry Benchmark Analysis'!F7+'Industry Benchmark Analysis'!F8)/2 -> 0.10162567 | F44: =AVERAGE('Industry Benchmark Analysis'!F2:F8) -> 0.05524128 | G44: Pre-COVID 2018–19 | H44: Post 2022
...

Sheet Sheet2

Sheet Covid Resilience
A1: COVID-19 Resilience Analysis (ROA-based)
A2: Bank | B2: Pre-COVID Avg ROA (2018-19) | C2: 2020 ROA (COVID Shock) | D2: ROA Drop (%) | E2: 2021-22 Recovery Avg ROA | F2: % of Pre-COVID ROA Recovered | G2: Post-2022 Avg ROA (2023-24) | H2: Fully Recovered? | I2: Resilience Ranking
A3: BoG | B3: ='Economic Phase Analysis'!B3 -> 0.028270135 | C3: ='Economic Phase Analysis'!C3 -> 0.015289913 | D3: =C3-B3 -> -0.012980222 | E3: ='Economic Phase Analysis'!D3 -> 0.035806709 | F3: =E3/B3 -> 1.2665913 | G3: ='Economic Phase Analysis'!E3 -> 0.048325267 | H3: Yes - exceeded | I3: 1st
A4: TBC | B4: ='Economic Phase Analysis'!B4 -> 0.031426262 | C4: ='Economic Phase Analysis'!C4 -> 0.016570701 | D4: =C4-B4 -> -0.014855561 | E4: ='Economic Phase Analysis'!D4 -> 0.037687935 | F4: =E4/B4 -> 1.1992497 | G4: ='Economic Phase Analysis'!E4 -> 0.03654845 | H4: Yes - exceeded | I4: 2nd
A5: Basis | B5: ='Economic Phase Analysis'!B5 -> 0.025880791 | C5: ='Economic Phase Analysis'!C5 -> 0.01285053 | D5: =C5-B5 -> -0.013030262 | E5: ='Economic Phase Analysis'!D5 -> 0.024112706 | F5: =E5/B5 -> 0.93168349 | G5: ='Economic Phase Analysis'!E5 -> 0.022706632 | H5: Partial | I5: 3rd
A6: Credo | B6: ='Economic Phase Analysis'!B6 -> 0.03104345 | C6: ='Economic Phase Analysis'!C6 -> 0.0091995276 | D6: =C6-B6 -> -0.021843922 | E6: ='Economic Phase Analysis'!D6 -> 0.023289332 | F6: =E6/B6 -> 0.75021726 | G6: ='Economic Phase Analysis'!E6 -> 0.021205274 | H6: Partial | I6: 4th
A7: VTB | B7: ='Economic Phase Analysis'!B7 -> 0.017213862 | C7: ='Economic Phase Analysis'!C7 -> 0.013977968 | D7: =C7-B7 -> -0.0032358941 | E7: ='Economic Phase Analysis'!D7 -> -0.022984882 | F7: =E7/B7 -> -1.3352543 | G7: ='Economic Phase Analysis'!E7 -> 0.0097342834 | H7: No - collapsed | I7: 5th
A10: ROE Resilience
A11: Bank | B11: Pre-COVID Avg ROE (2018-19) | C11: 2020 ROE (COVID Shock) | D11: ROE Drop (%) | E11: 2021-22 Recovery Avg ROE | F11: % of Pre-COVID ROE Recovered | G11: Post-2022 Avg ROE (2023-24) | H11: Fully Recovered? | I11: Resilience Ranking
A12: BoG | B12: ='Economic Phase Analysis'!B12 -> 0.24159159 | C12: ='Economic Phase Analysis'!C12 -> 0.13426121 | D12: =C12-B12 -> -0.10733038 | E12: ='Economic Phase Analysis'!D12 -> 0.30417817 | F12: =E12/B12 -> 1.2590594 | G12: ='Economic Phase Analysis'!E12 -> 0.34415571 | H12: Yes - exceeded | I12: 1st
A13: TBC | B13: ='Economic Phase Analysis'!B13 -> 0.22693262 | C13: ='Economic Phase Analysis'!C13 -> 0.12579893 | D13: =C13-B13 -> -0.1011337 | E13: ='Economic Phase Analysis'!D13 -> 0.2615259 | F13: =E13/B13 -> 1.1524385 | G13: ='Economic Phase Analysis'!E13 -> 0.24615402 | H13: Yes - exceeded | I13: 2nd
A14: Basis | B14: ='Economic Phase Analysis'!B14 -> 0.15054923 | C14: ='Economic Phase Analysis'!C14 -> 0.081754786 | D14: =C14-B14 -> -0.068794444 | E14: ='Economic Phase Analysis'!D14 -> 0.072893545 | F14: =E14/B14 -> 0.48418411 | G14: ='Economic Phase Analysis'!E14 -> 0.15469873 | H14: Partial | I14: 4th
A15: Credo | B15: ='Economic Phase Analysis'!B15 -> 0.1854681 | C15: ='Economic Phase Analysis'!C15 -> 0.068650696 | D15: =C15-B15 -> -0.1168174 | E15: ='Economic Phase Analysis'!D15 -> 0.18711724 | F15: =E15/B15 -> 1.0088918 | G15: ='Economic Phase Analysis'!E15 -> 0.021205274 | H15: Partial | I15: 3rd
A16: VTB | B16: ='Economic Phase Analysis'!B16 -> 0.11104735 | C16: ='Economic Phase Analysis'!C16 -> 0.09015771 | D16: =C16-B16 -> -0.020889641 | E16: ='Economic Phase Analysis'!D16 -> -0.067446305 | F16: =E16/B16 -> -0.60736527 | G16: ='Economic Phase Analysis'!E16 -> 0.013523072 | H16: No - collapsed | I16: 5th

Sheet Correlation Analysis
A1: Independent Variable | B1: Corr. with ROA | C1: Corr. with ROE | E1: All 5 banks, 2018-2024
A2: Net Interest Margin (NIM) | B2: =CORREL(Calculated_Ratios!C2:C36,Calculated_Ratios!E2:E36) -> 0.18514248 | C2: =CORREL(Calculated_Ratios!D2:D36,Calculated_Ratios!E2:E36) -> 0.19919535
A3: Cost-to-Income (CIR) | B3: =CORREL(Calculated_Ratios!C2:C36,Calculated_Ratios!F2:F36) -> 0.35508979 | C3: =CORREL(Calculated_Ratios!D2:D36,Calculated_Ratios!F2:F36) -> 0.13545701
A4: NPL Ratio | B4: =CORREL(Calculated_Ratios!C2:C36,Calculated_Ratios!G2:G36) -> -0.34430058 | C4: =CORREL(Calculated_Ratios!D2:D36,Calculated_Ratios!G2:G36) -> -0.49403499
A5: Loan-to-Asset Ratio | B5: =CORREL(Calculated_Ratios!C2:C36,Calculated_Ratios!H2:H36) -> 0.54160622 | C5: =CORREL(Calculated_Ratios!D2:D36,Calculated_Ratios!H2:H36) -> 0.5049544
A6: Equity Multiplier | B6: =CORREL(Calculated_Ratios!C2:C36,Calculated_Ratios!I2:I36) -> 0.43717808 | C6: =CORREL(Calculated_Ratios!D2:D36,Calculated_Ratios!I2:I36) -> 0.62321707
A9: Independent Variable | B9: Corr. with ROA | C9: Corr. With ROE | E9: excluding VTB, to remove outliers
A10: Net Interest Margin (NIM) | B10: =CORREL(Calculated_Ratios!C2:C29,Calculated_Ratios!E2:E29) -> -0.1378545 | C10: =CORREL(Calculated_Ratios!D2:D29,Calculated_Ratios!E2:E29) -> -0.14848107
A11: Cost-to-Income (CIR) | B11: =CORREL(Calculated_Ratios!C2:C29,Calculated_Ratios!F2:F29) -> -0.58868358 | C11: =CORREL(Calculated_Ratios!D2:D29,Calculated_Ratios!F2:F29) -> -0.62823014
A12: NPL Ratio | B12: =CORREL(Calculated_Ratios!C2:C29,Calculated_Ratios!G2:G29) -> -0.31412335 | C12: =CORREL(Calculated_Ratios!D2:D29,Calculated_Ratios!G2:G29) -> -0.35110544
A13: Loan-to-Asset Ratio | B13: =CORREL(Calculated_Ratios!C2:C29,Calculated_Ratios!H2:H29) -> -0.20760512 | C13: =CORREL(Calculated_Ratios!D2:D29,Calculated_Ratios!H2:H29) -> -0.20869459
A14: Equity Multiplier | B14: =CORREL(Calculated_Ratios!C2:C29,Calculated_Ratios!I2:I29) -> -0.075886738 | C14: =CORREL(Calculated_Ratios!D2:D29,Calculated_Ratios!I2:I29) -> 0.26593674

Sheet Key Findings
A1: Bank | B1: Avg ROA | C1: Avg ROE | D1: Avg NIM | E1: Avg CIR | F1: Avg NPL | G1: Avg Loan-to-Asset | H1: Avg Equity Multiplier
A2: BoG | B2: =AVERAGE(Calculated_Ratios!C2:C8) -> 0.034299162 | C2: =AVERAGE(Calculated_Ratios!D2:D8) -> 0.27344459 | D2: =AVERAGE(Calculated_Ratios!E2:E8) -> 0.047496839 | E2: =AVERAGE(Calculated_Ratios!F2:F8) -> 0.33326858 | F2: =AVERAGE(Calculated_Ratios!G2:G8) -> 0.027978899 | G2: =AVERAGE(Calculated_Ratios!H2:H8) -> 0.34916321 | H2: =AVERAGE(Calculated_Ratios!I2:I8) -> 8.1503363
A3: TBC | B3: =AVERAGE(Calculated_Ratios!C9:C15) -> 0.032556571 | C3: =AVERAGE(Calculated_Ratios!D9:D15) -> 0.22786057 | D3: =AVERAGE(Calculated_Ratios!E9:E15) -> 0.046844109 | E3: =AVERAGE(Calculated_Ratios!F9:F15) -> 0.33733216 | F3: =AVERAGE(Calculated_Ratios!G9:G15) -> 0.027571426 | G3: =AVERAGE(Calculated_Ratios!H9:H15) -> 0.36101907 | H3: =AVERAGE(Calculated_Ratios!I9:I15) -> 7.0575558
A4: Basis | B4: =AVERAGE(Calculated_Ratios!C16:C22) -> 0.022607256 | C4: =AVERAGE(Calculated_Ratios!D16:D22) -> 0.14184214 | D4: =AVERAGE(Calculated_Ratios!E16:E22) -> 0.038967582 | E4: =AVERAGE(Calculated_Ratios!F16:F22) -> 0.46058128 | F4: =AVERAGE(Calculated_Ratios!G16:G22) -> 0.047144121 | G4: =AVERAGE(Calculated_Ratios!H16:H22) -> 0.34889354 | H4: =AVERAGE(Calculated_Ratios!I16:I22) -> 6.2916675
A5: Credo | B5: =AVERAGE(Calculated_Ratios!C23:C29) -> 0.02289652 | C5: =AVERAGE(Calculated_Ratios!D23:D29) -> 0.16543206 | D5: =AVERAGE(Calculated_Ratios!E23:E29) -> 0.11986014 | E5: =AVERAGE(Calculated_Ratios!F23:F29) -> 0.61723974 | F5: =AVERAGE(Calculated_Ratios!G23:G29) -> 0.0092137982 | G5: =AVERAGE(Calculated_Ratios!H23:H29) -> 0.46422385 | H5: =AVERAGE(Calculated_Ratios!I23:I29) -> 7.3818969
A6: VTB | B6: =AVERAGE(Calculated_Ratios!C30:C36) -> 0.0031292134 | C6: =AVERAGE(Calculated_Ratios!D30:D36) -> 0.02920085 | D6: =AVERAGE(Calculated_Ratios!E30:E36) -> 0.031859082 | E6: =AVERAGE(Calculated_Ratios!F30:F36) -> 0.48780154 | F6: =AVERAGE(Calculated_Ratios!G30:G36) -> 0.16429816 | G6: =AVERAGE(Calculated_Ratios!H30:H36) -> 0.28269704 | H6: =AVERAGE(Calculated_Ratios!I30:I36) -> 4.5795928
A9: Category | B9: Best Bank | C9: Weakest Bank
A10: Profitability (ROE) | B10: BoG | C10: VTB
A11: Asset Utilization (ROA) | B11: BoG | C11: VTB
A12: Efficiency (CIR) | B12: BoG | C12: Credo | E12: LOWER
A13: Asset Quality (NPL) | B13: Credo | C13: VTB | E13: LOWER
A14: Lending Intensity (Loan-to-Asset) | B14: VTB | C14: Credo | E14: LOWER
A15: Highest/Lowest Leverage | B15: VTB | C15: BoG | E15: LOWER
A18: Research Area | B18: Main Finding
A19: Profitability leaders | B19: BOG and TBC consistently maintained the highest ROE and ROA levels relative to industry averages
A20: Most efficient bank | B20: BOG maintained the lowest average cost-to-income ratio during most years
A21: Weakest asset quality | B21: VTB exhibited persistently weaker asset-quality indicators relative to peer banks
A22: Strongest COVID recovery | B22: TBC recovered profitability levels faster than smaller banks after the 2020 decline.
A23: Most consistent underperformer | B23: VTB is underperformer
A32: Metric | B32: ROA Efficiency | C32: ROE Shareholder Return | D32: NIM Spread | E32: CIR (Inverted) | F32: NPL (Inverted)
A33: BoG | B33: =10 * (B2 - MIN($B$2:$B$6)) / (MAX($B$2:$B$6) - MIN($B$2:$B$6)) -> 10 | C33: =10 * (C2 - MIN($C$2:$C$6)) / (MAX($C$2:$C$6) - MIN($C$2:$C$6)) -> 10 | D33: =10 * (D2 - MIN($D$2:$D$6)) / (MAX($D$2:$D$6) - MIN($D$2:$D$6)) -> 1.7769965 | E33: =10 * (E2 - MAX($E$2:$E$6)) / (MIN($E$2:$E$6) - MAX($E$2:$E$6)) -> 10 | F33: =10 * (F2 - MAX($F$2:$F$6)) / (MIN($F$2:$F$6) - MAX($F$2:$F$6)) -> 8.7900068
A34: TBC | B34: =10 * (B3 - MIN($B$2:$B$6)) / (MAX($B$2:$B$6) - MIN($B$2:$B$6)) -> 9.4409386 | C34: =10 * (C3 - MIN($C$2:$C$6)) / (MAX($C$2:$C$6) - MIN($C$2:$C$6)) -> 8.1336668 | D34: =10 * (D3 - MIN($D$2:$D$6)) / (MAX($D$2:$D$6) - MIN($D$2:$D$6)) -> 1.7028235 | E34: =10 * (E3 - MAX($E$2:$E$6)) / (MIN($E$2:$E$6) - MAX($E$2:$E$6)) -> 9.8569017 | F34: =10 * (F3 - MAX($F$2:$F$6)) / (MIN($F$2:$F$6) - MAX($F$2:$F$6)) -> 8.8162811
A35: BasisBank | B35: =10 * (B4 - MIN($B$2:$B$6)) / (MAX($B$2:$B$6) - MIN($B$2:$B$6)) -> 6.2489812 | C35: =10 * (C4 - MIN($C$2:$C$6)) / (MAX($C$2:$C$6) - MIN($C$2:$C$6)) -> 4.6118395 | D35: =10 * (D4 - MIN($D$2:$D$6)) / (MAX($D$2:$D$6) - MIN($D$2:$D$6)) -> 0.80777443 | E35: =10 * (E4 - MAX($E$2:$E$6)) / (MIN($E$2:$E$6) - MAX($E$2:$E$6)) -> 5.516703 | F35: =10 * (F4 - MAX($F$2:$F$6)) / (MIN($F$2:$F$6) - MAX($F$2:$F$6)) -> 7.5542135
A36: Credo | B36: =10 * (B5 - MIN($B$2:$B$6)) / (MAX($B$2:$B$6) - MIN($B$2:$B$6)) -> 6.3417834 | C36: =10 * (C5 - MIN($C$2:$C$6)) / (MAX($C$2:$C$6) - MIN($C$2:$C$6)) -> 5.5776744 | D36: =10 * (D5 - MIN($D$2:$D$6)) / (MAX($D$2:$D$6) - MIN($D$2:$D$6)) -> 10 | E36: =10 * (E5 - MAX($E$2:$E$6)) / (MIN($E$2:$E$6) - MAX($E$2:$E$6)) -> 0 | F36: =10 * (F5 - MAX($F$2:$F$6)) / (MIN($F$2:$F$6) - MAX($F$2:$F$6)) -> 10
A37: VTB | B37: =10 * (B6 - MIN($B$2:$B$6)) / (MAX($B$2:$B$6) - MIN($B$2:$B$6)) -> 0 | C37: =10 * (C6 - MIN($C$2:$C$6)) / (MAX($C$2:$C$6) - MIN($C$2:$C$6)) -> 0 | D37: =10 * (D6 - MIN($D$2:$D$6)) / (MAX($D$2:$D$6) - MIN($D$2:$D$6)) -> 0 | E37: =10 * (E6 - MAX($E$2:$E$6)) / (MIN($E$2:$E$6) - MAX($E$2:$E$6)) -> 4.5581459 | F37: =10 * (F6 - MAX($F$2:$F$6)) / (MIN($F$2:$F$6) - MAX($F$2:$F$6)) -> 0

Sheet Conclusions

Sheet ROE Trend
A3: Average of ROE | B3: Column Labels
A4: Row Labels | B4: Basis | C4: BoG | D4: Credo | E4: TBC | F4: VTB | G4: Grand Total
A5: 2018 | B5: 0.16107986 | C5: 0.21383982 | D5: 0.16156225 | E5: 0.21883181 | F5: 0.11162034 | G5: 0.17338681
A6: 2019 | B6: 0.14001861 | C6: 0.26934336 | D6: 0.20937395 | E6: 0.23503344 | F6: 0.11047437 | G6: 0.19284874
A7: 2020 | B7: 0.081754786 | C7: 0.13426121 | D7: 0.068650696 | E7: 0.12579893 | F7: 0.09015771 | G7: 0.10012467
A8: 2021 | B8: 0.11685989 | C8: 0.26854695 | D8: 0.18925168 | E8: 0.26259008 | F8: 0.095153324 | G8: 0.18648038
A9: 2022 | B9: 0.18378441 | C9: 0.33980938 | D9: 0.18498281 | E9: 0.26046172 | F9: -0.23004593 | G9: 0.14779848
A10: 2023 | B10: 0.15777383 | C10: 0.32374107 | D10: 0.14375715 | E10: 0.24830679 | F10: 0.001245551 | G10: 0.17496488
A11: 2024 | B11: 0.15162363 | C11: 0.36457034 | D11: 0.20044586 | E11: 0.24400125 | F11: 0.025800593 | G11: 0.19728833
A12: Grand Total | B12: 0.14184214 | C12: 0.27344459 | D12: 0.16543206 | E12: 0.22786057 | F12: 0.02920085 | G12: 0.16755604
A17: Row Labels | B17: Basis | C17: BoG | D17: Credo | E17: TBC | F17: VTB | G17: Industry
A18: 2018 | B18: 0.16107986 | C18: 0.21383982 | D18: 0.16156225 | E18: 0.21883181 | F18: 0.11162034 | G18: 0.1734
A19: 2019 | B19: 0.14001861 | C19: 0.26934336 | D19: 0.20937395 | E19: 0.23503344 | F19: 0.11047437 | G19: 0.1928
A20: 2020 | B20: 0.081754786 | C20: 0.13426121 | D20: 0.068650696 | E20: 0.12579893 | F20: 0.09015771 | G20: 0.1001
A21: 2021 | B21: 0.11685989 | C21: 0.26854695 | D21: 0.18925168 | E21: 0.26259008 | F21: 0.095153324 | G21: 0.1865
A22: 2022 | B22: 0.18378441 | C22: 0.33980938 | D22: 0.18498281 | E22: 0.26046172 | F22: -0.23004593 | G22: 0.1478
A23: 2023 | B23: 0.15777383 | C23: 0.32374107 | D23: 0.14375715 | E23: 0.24830679 | F23: 0.001245551 | G23: 0.175
A24: 2024 | B24: 0.15162363 | C24: 0.36457034 | D24: 0.20044586 | E24: 0.24400125 | F24: 0.025800593 | G24: 0.1973

Sheet NIM_approx Trend
A3: Average of NIM_approx | B3: Column Labels
A4: Row Labels | B4: Basis | C4: BoG | D4: Credo | E4: TBC | F4: VTB | G4: Grand Total
A5: 2018 | B5: 0.041777184 | C5: 0.053900371 | D5: 0.14543076 | E5: 0.054283597 | F5: 0.041698573 | G5: 0.067418097
A6: 2019 | B6: 0.037897767 | C6: 0.047710752 | D6: 0.13488727 | E6: 0.046993579 | F6: 0.038587737 | G6: 0.061215422
A7: 2020 | B7: 0.028858913 | C7: 0.038162476 | D7: 0.10641391 | E7: 0.040667594 | F7: 0.036695697 | G7: 0.050159718
A8: 2021 | B8: 0.033972572 | C8: 0.041882622 | D8: 0.1224519 | E8: 0.042886508 | F8: 0.040806806 | G8: 0.056400081
A9: 2022 | B9: 0.049156401 | C9: 0.045590935 | D9: 0.11160771 | E9: 0.047474893 | F9: 0.023925149 | G9: 0.055551019
A10: 2023 | B10: 0.040203918 | C10: 0.053077945 | D10: 0.10901717 | E10: 0.049770129 | F10: 0.024588707 | G10: 0.055331573
A11: 2024 | B11: 0.04090632 | C11: 0.05215277 | D11: 0.10921224 | E11: 0.045832462 | F11: 0.016710903 | G11: 0.052962939
A12: Grand Total | B12: 0.038967582 | C12: 0.047496839 | D12: 0.11986014 | E12: 0.046844109 | F12: 0.031859082 | G12: 0.05700555
A17: Row Labels | B17: Basis | C17: BoG | D17: Credo | E17: TBC | F17: VTB | G17: Industry
A18: 2018 | B18: 0.041777184 | C18: 0.053900371 | D18: 0.14543076 | E18: 0.054283597 | F18: 0.041698573 | G18: 0.0674
A19: 2019 | B19: 0.037897767 | C19: 0.047710752 | D19: 0.13488727 | E19: 0.046993579 | F19: 0.038587737 | G19: 0.0612
A20: 2020 | B20: 0.028858913 | C20: 0.038162476 | D20: 0.10641391 | E20: 0.040667594 | F20: 0.036695697 | G20: 0.0502
A21: 2021 | B21: 0.033972572 | C21: 0.041882622 | D21: 0.1224519 | E21: 0.042886508 | F21: 0.040806806 | G21: 0.0564
A22: 2022 | B22: 0.049156401 | C22: 0.045590935 | D22: 0.11160771 | E22: 0.047474893 | F22: 0.023925149 | G22: 0.0556
A23: 2023 | B23: 0.040203918 | C23: 0.053077945 | D23: 0.10901717 | E23: 0.049770129 | F23: 0.024588707 | G23: 0.0553
A24: 2024 | B24: 0.04090632 | C24: 0.05215277 | D24: 0.10921224 | E24: 0.045832462 | F24: 0.016710903 | G24: 0.053

Sheet CIR_Trend
A3: Average of CIR | B3: Column Labels
A4: Row Labels | B4: Basis | C4: BoG | D4: Credo | E4: TBC | F4: VTB | G4: Grand Total
A5: 2018 | B5: 0.37268495 | C5: 0.35951998 | D5: 0.67948707 | E5: 0.37138738 | F5: 0.61266358 | G5: 0.47914859
A6: 2019 | B6: 0.43840541 | C6: 0.37174504 | D6: 0.6308682 | E6: 0.37721121 | F6: 0.65468674 | G6: 0.49458332
A7: 2020 | B7: 0.46910666 | C7: 0.37568995 | D7: 0.66233793 | E7: 0.35092098 | F7: 0.82404181 | G7: 0.53641947
A8: 2021 | B8: 0.49914505 | C8: 0.35354852 | D8: 0.58775125 | E8: 0.32548136 | F8: 0.58261711 | G8: 0.46970866
A9: 2022 | B9: 0.47664688 | C9: 0.30117531 | D9: 0.58438311 | E9: 0.2882168 | F9: -0.61455105 | G9: 0.20717421
A10: 2023 | B10: 0.47628707 | C10: 0.28141708 | D10: 0.61014925 | E10: 0.319759 | F10: 0.88861967 | G10: 0.51524641
A11: 2024 | B11: 0.49179298 | C11: 0.28978421 | D11: 0.56570133 | E11: 0.3283484 | F11: 0.46653295 | G11: 0.42843197
A12: Grand Total | B12: 0.46058128 | C12: 0.33326858 | D12: 0.61723974 | E12: 0.33733216 | F12: 0.48780154 | G12: 0.44724466
